<?xml version="1.0"?>

<!-- https://wiki.ros.org/urdf/XML/link -->

<robot name="robot_example">

    <!-- Definindo Cores -->

    <!-- Cor Vermelha -->
    <material name="red">
        <color rgba="0.8 0 0 1"/>
    </material>

    <!-- Cor Verde -->
    <material name="green">
        <color rgba="0 0.8 0 1"/>
    </material>

    <!-- Cor Azul -->
    <material name="blue">
        <color rgba="0 0 0.8 1"/>
    </material>

    <!-- Cor Amarela -->
    <material name="yellow">
        <color rgba="1 1 0 1"/>
    </material>

    <!-- Cor Ciano -->
    <material name="cyan">
        <color rgba="0 1 1 1"/>
    </material>

    <!-- Modelando o Robo: Puma560-->

    <!-- Aqui, adicionamos um link "fictício" mundo e uma junta fixa para fixar o robô ao mundo. 
        É importante para a simulação no gazebo, mas não é necessário para o Rviz.-->

    <!-- Link: world-->
    <link name="world"/>

    <!-- Joint 0: world para base_link-->
    <joint name="fixed_joint" type="fixed">
        <origin rpy="0 0 0" xyz="0 0 0"/>
        <parent link="world"/>
        <child link="base_link"/>
    </joint>

    <!-- Link 0: base_link -->
    <link name="base_link">
        <visual>
            <geometry>
                <cylinder length="0.2" radius="0.4"/>
            </geometry>
            <origin rpy="0 0 0" xyz="0 0 0"/>
            <material name="green"/>
        </visual>
    </link>

    <!-- Junta 1: base_link para link_1 -->
    <joint name="joint_1" type="revolute">
        <parent link="base_link"/>
        <child link="link_1"/>
        <origin rpy="0 0 0" xyz="0 0 0.1"/>
        <axis xyz="0 0 1"/>
        <limit effort="300" velocity="2.0" lower="-3.141593" upper="3.141593"/>
    </joint>  

    <!-- Link 1: link_1 -->
    <link name="link_1">
        <visual>
            <geometry>
                <cylinder length="0.6" radius="0.15"/>
            </geometry>
            <origin rpy="0 0 0" xyz="0 0 0.3"/>
            <material name="yellow"/>
        </visual>
    </link>

    <!-- Junta 2: link_1 para link_2 -->
    <joint name="joint_2" type="revolute">
        <parent link="link_1"/>
        <child link="link_2"/>
        <origin rpy="0 -1.570796 0" xyz="-0.15 0 0.5"/>
        <axis xyz="0 0 1"/>
        <limit effort="300" velocity="2.0" lower="-3.141593" upper="3.141593"/>
    </joint>

    <!-- Link 2: link_2 -->
    <link name="link_2">
        <visual>
            <geometry>
                <cylinder length="1" radius="0.1"/>
            </geometry>
            <origin rpy="0 1.570796 0" xyz="0.3 0 0.1"/>
            <material name="red"/>
        </visual>
    </link>

    <!-- Junta 3: link_2 para link_3 -->
    <joint name="joint_3" type="revolute">
        <parent link="link_2"/>
        <child link="link_3"/>
        <origin rpy="0 0 0" xyz="0.7 0 0"/>
        <axis xyz="0 0 1"/>
        <limit effort="300" velocity="2.0" lower="-3.141593" upper="3.141593"/>
    </joint>

    <!-- Link 3: link_3 -->
    <link name="link_3">
        <visual>
            <geometry>
                <cylinder length="1" radius="0.1"/>
            </geometry>
            <origin rpy="0 1.570796 0" xyz="0.4 0 -0.1"/>
            <material name="yellow"/>
        </visual>
    </link>

    <!-- Junta 4: link_3 para link_4 -->
    <joint name="joint_4" type="revolute">
        <parent link="link_3"/>
        <child link="link_4"/>
        <origin rpy="0 0 0" xyz="1 0 -0.1"/>
        <axis xyz="0 0 1"/>
        <limit effort="300" velocity="2.0" lower="-3.141593" upper="3.141593"/>
    </joint>

    <!-- Link 4: link_4 -->
    <link name="link_4">
        <visual>
            <geometry>
                <cylinder length="0.4" radius="0.1"/>
            </geometry>
            <origin rpy="0 0 0" xyz="0 0 0.1"/>
            <material name="blue"/>
        </visual>
    </link>

    <!-- Junta 5: link_4 para link_5 -->
    <joint name="joint_5" type="revolute">
        <parent link="link_4"/>
        <child link="link_5"/>
        <origin rpy="0 1.570796 0" xyz="0 0 0.4"/>
        <axis xyz="0 0 1"/>
        <limit effort="300" velocity="2.0" lower="-3.141593" upper="3.141593"/>
    </joint>

    <!-- Link 5: link_5 -->
    <link name="link_5">
        <visual>
            <geometry>
                <cylinder length="0.4" radius="0.1"/>
            </geometry>
            <origin rpy="0 0 0" xyz="0 0 0.1"/>
            <material name="blue"/>
        </visual>
    </link>

    <!-- Junta 6: link_5 para link_6 -->
    <joint name="joint_6" type="revolute">
        <parent link="link_5"/>
        <child link="link_6"/>
        <origin rpy="-1.570796 0 0" xyz="0 0 0.4"/>
        <axis xyz="0 0 1"/>
        <limit effort="300" velocity="2.0" lower="-3.141593" upper="3.141593"/>
    </joint>

    <!-- Link 6: link_6 -->
    <link name="link_6">
        <visual>
            <geometry>
                <cylinder length="0.3" radius="0.1"/>
            </geometry>
            <origin rpy="0 0 0" xyz="0 0 0.1"/>
            <material name="red"/>
        </visual>
    </link>

    <!-- Modelando o End - Effector -->

    <!-- Junta 7: link_6 para link_7 -->
    <joint name="joint_7" type="prismatic">
        <parent link="link_6"/>
        <child link="link_7"/>
        <origin rpy="0 0 0" xyz="0.08 0 0.25"/>
        <axis xyz="1 0 0"/>
        <limit effort="300" velocity="2.0" lower="-3.141593" upper="3.141593"/>
    </joint>

    <!-- Link 7: link_7 -->
    <link name="link_7">
        <visual>
            <geometry>
                <box size="0.03 0.06 0.15"/>
            </geometry>
            <origin rpy="0 0 0" xyz="0 0 0.075"/>
            <material name="yellow"/>
        </visual>
    </link>

    <!-- Junta 8: link_6 para link_8 -->
    <joint name="joint_8" type="prismatic">
        <parent link="link_6"/>
        <child link="link_8"/>
        <origin rpy="0 0 0" xyz="-0.08 0 0.25"/>
        <axis xyz="1 0 0"/>
        <limit effort="300" velocity="2.0" lower="-3.141593" upper="3.141593"/>
    </joint>

    <!-- Link 8: link_8 -->
    <link name="link_8">
        <visual>
            <geometry>
                <box size="0.03 0.06 0.15"/>
            </geometry>
            <origin rpy="0 0 0" xyz="0 0 0.075"/>
            <material name="yellow"/>
        </visual>
    </link>

</robot>
